Workbook

Sheet Parameters
A1: PARAMETERS & ASSUMPTIONS
A2: EUR/R exchange rate | B2: 19.2
A3: inflation | B3: 0.04
A4: corporate tax rate | B4: 0.25
A5: EV (Ebitda multiple) | B5: 5
A6: Net Asset Value | B6: 85000
A7: Investor club interest | B7: 0.06
A8: Base price/ KG (1.2% USK/ 32%TKR) | B8: 58
A9: OPEX/ Ha | B9: 70000
A10: Amount of planted HA | B10: 155
A11: Manager salary | B11: 655000
A13: Mac prices (2026) realistic
A14: 695 Beaumont | B14: 48 | D14: (EUR * 1000) | E14: 2026 | F14: 2027 | G14: 2028 | H14: 2029 | I14: 2030 | J14: 2031
A15: 816 | B15: 61.5 | D15: Enterprise value (EBITDA multiple) | E15: 4521.2766 | F15: 4702.1277 | G15: 4890.2128 | H15: 5085.8213 | I15: 5289.2541 | J15: 5500.8243
A16: A4 | B16: 59.5 | D16: EBITDA | E16: 708.86136 | F16: 810.74604 | G16: 891.6968 | H16: 984.39054 | I16: 1083.6773 | J16: 1176.4478
A17: Nelmac | B17: 49.5 | D17: Equity Value | E17: 1405.7488 | F17: 2181.3615 | G17: 3024.9214 | H17: 3948.8494 | I17: 4958.3912 | J17: 6048.9728
A19: Mac prices (2026) conservative
A20: 695 Beaumont | B20: 39 | D20: (EUR * 1000) | E20: 2026 | F20: 2027 | G20: 2028 | H20: 2029 | I20: 2030 | J20: 2031
A21: 816 | B21: 63.97 | D21: Enterprise value (EBITDA multiple) | E21: 4521.2766 | F21: 4702.1277 | G21: 4890.2128 | H21: 5085.8213 | I21: 5289.2541 | J21: 5500.8243
A22: A4 | B22: 63.14 | D22: EBITDA | E22: 604.46308 | F22: 700.02189 | G22: 777.75942 | H22: 867.24047 | I22: 963.03223 | J22: 1051.4052
A23: Nelmac | B23: 48 | D23: Equity Value | E23: 1327.4501 | F23: 2020.0197 | G23: 2778.1265 | H23: 3614.192 | I23: 4533.2501 | J23: 5530.0497

Sheet Orchard
A1: Block name | B1: Cultivar | C1: Trees/ ha | D1: Ha volgens oes data | E1: Ha | F1: No of trees | G1: Spacing | H1: Irrigation | I1: Plant date | J1: Age | K1: DNIS 2023 | L1: 2024 | M1: 2025 | N1: 2026 | O1: =N1+1 -> 2027 | P1: =O1+1 -> 2028 | Q1: =P1+1 -> 2029 | R1: =Q1+1 -> 2030 | S1: =R1+1 -> 2031 | T1: =S1+1 -> 2032 | U1: =T1+1 -> 2033 | V1: =U1+1 -> 2034 | W1: =V1+1 -> 2035
A2: 1 | B2: 695 Beaumont | C2: 476 | E2: 2.45 | F2: 1166.2 | G2: 7.00 X 3.00 | H2: Micros | I2: 42313 | J2: 10 | K2: 6728.4 | L2: 13265 | M2: 11169 | N2: =(L2+M2)/2 -> 12217 | O2: =N2 -> 12217 | P2: =O2 -> 12217 | Q2: =P2 -> 12217 | R2: =Q2 -> 12217 | S2: =R2 -> 12217 | T2: =S2 -> 12217 | U2: =T2 -> 12217 | V2: =U2 -> 12217 | W2: =V2 -> 12217
A3: 2 | B3: 695 Beaumont | C3: 476 | E3: 0.81 | F3: 385.56 | G3: 7.00 X 3.00 | H3: Micros | I3: 42313 | J3: 10 | K3: 2430 | L3: 4177 | M3: 4996 | N3: =(L3+M3)/2 -> 4586.5 | O3: =N3 -> 4586.5 | P3: =O3 -> 4586.5 | Q3: =P3 -> 4586.5 | R3: =Q3 -> 4586.5 | S3: =R3 -> 4586.5 | T3: =S3 -> 4586.5 | U3: =T3 -> 4586.5 | V3: =U3 -> 4586.5 | W3: =V3 -> 4586.5
A4: 3 | B4: 695 Beaumont | C4: 476 | E4: 2 | F4: 952 | G4: 7.00 X 3.00 | H4: Micros | I4: 42313 | J4: 10 | K4: 5246.64 | L4: 12512 | M4: 10822 | N4: =(L4+M4)/2 -> 11667 | O4: =N4 -> 11667 | P4: =O4 -> 11667 | Q4: =P4 -> 11667 | R4: =Q4 -> 11667 | S4: =R4 -> 11667 | T4: =S4 -> 11667 | U4: =T4 -> 11667 | V4: =U4 -> 11667 | W4: =V4 -> 11667
A5: 4 | B5: 695 Beaumont | C5: 476 | D5: 2 | E5: 2.25 | F5: 1071 | G5: 7.00 X 3.00 | H5: Micros | I5: 42313 | J5: 10 | K5: 6434.64 | L5: 12072 | M5: 12528 | N5: =(L5+M5)/2 -> 12300 | O5: =N5 -> 12300 | P5: =O5 -> 12300 | Q5: =P5 -> 12300 | R5: =Q5 -> 12300 | S5: =R5 -> 12300 | T5: =S5 -> 12300 | U5: =T5 -> 12300 | V5: =U5 -> 12300 | W5: =V5 -> 12300
A6: 5 | B6: 695 Beaumont | C6: 476 | E6: 1.45 | F6: 690.2 | G6: 7.00 X 3.00 | H6: Micros | I6: 42313 | J6: 10 | K6: 4235.76 | L6: 8303 | M6: 7219 | N6: =(L6+M6)/2 -> 7761 | O6: =N6 -> 7761 | P6: =O6 -> 7761 | Q6: =P6 -> 7761 | R6: =Q6 -> 7761 | S6: =R6 -> 7761 | T6: =S6 -> 7761 | U6: =T6 -> 7761 | V6: =U6 -> 7761 | W6: =V6 -> 7761
A7: 6 | B7: 695 Beaumont | C7: 476 | E7: 0.6 | F7: 285.6 | G7: 7.00 X 3.00 | H7: Micros | I7: 42313 | J7: 10 | K7: 2324.16 | L7: 4025 | M7: 3465 | N7: =(L7+M7)/2 -> 3745 | O7: =N7 -> 3745 | P7: =O7 -> 3745 | Q7: =P7 -> 3745 | R7: =Q7 -> 3745 | S7: =R7 -> 3745 | T7: =S7 -> 3745 | U7: =T7 -> 3745 | V7: =U7 -> 3745 | W7: =V7 -> 3745
A8: 7 | B8: 695 Beaumont | C8: 476 | E8: 1.62 | F8: 771.12 | G8: 7.00 X 3.00 | H8: Micros | I8: 42313 | J8: 10 | K8: 6426 | L8: 8827 | M8: 8251 | N8: =(L8+M8)/2 -> 8539 | O8: =N8 -> 8539 | P8: =O8 -> 8539 | Q8: =P8 -> 8539 | R8: =Q8 -> 8539 | S8: =R8 -> 8539 | T8: =S8 -> 8539 | U8: =T8 -> 8539 | V8: =U8 -> 8539 | W8: =V8 -> 8539
A9: 8 | B9: 695 Beaumont | C9: 476 | E9: 1.55 | F9: 737.8 | G9: 7.00 X 3.00 | H9: Micros | I9: 42313 | J9: 10 | K9: 6147.36 | L9: 8675 | M9: 7599 | N9: =(L9+M9)/2 -> 8137 | O9: =N9 -> 8137 | P9: =O9 -> 8137 | Q9: =P9 -> 8137 | R9: =Q9 -> 8137 | S9: =R9 -> 8137 | T9: =S9 -> 8137 | U9: =T9 -> 8137 | V9: =U9 -> 8137 | W9: =V9 -> 8137
A10: 9 | B10: 695 Beaumont | C10: 476 | E10: 1.33 | F10: 633.08 | G10: 7.00 X 3.00 | H10: Micros | I10: 42313 | J10: 10 | K10: 4726.08 | L10: 4512 | M10: 4480 | N10: =(L10+M10)/2 -> 4496 | O10: =N10 -> 4496 | P10: =O10 -> 4496 | Q10: =P10 -> 4496 | R10: =Q10 -> 4496 | S10: =R10 -> 4496 | T10: =S10 -> 4496 | U10: =T10 -> 4496 | V10: =U10 -> 4496 | W10: =V10 -> 4496
A11: Dallas Bo | B11: 695 Beaumont | C11: 476 | D11: 4.85 | E11: 5 | F11: 2380 | G11: 7.00 X 3.00 | H11: Micros | I11: 43053 | J11: 8 | K11: 14463.36 | L11: 18337 | M11: 17474 | N11: =(L11+M11)/2*1.15 -> 20591.325 | O11: =N11*1.15 -> 23680.024 | P11: =O11 -> 23680.024 | Q11: =P11 -> 23680.024 | R11: =Q11 -> 23680.024 | S11: =R11 -> 23680.024 | T11: =S11 -> 23680.024 | U11: =T11 -> 23680.024 | V11: =U11 -> 23680.024 | W11: =V11 -> 23680.024
A12: Dallas Fase 1 | B12: 695 Beaumont | C12: 416 | D12: 4.83 | E12: 5 | F12: 2080 | G12: 8.00 X 3.00 | H12: Micros | I12: 43053 | J12: 8 | K12: 15994.8 | L12: 21394 | M12: 17029 | N12: =(L12+M12)/2*1.15 -> 22093.225 | O12: =N12*1.15 -> 25407.209 | P12: =O12 -> 25407.209 | Q12: =P12 -> 25407.209 | R12: =Q12 -> 25407.209 | S12: =R12 -> 25407.209 | T12: =S12 -> 25407.209 | U12: =T12 -> 25407.209 | V12: =U12 -> 25407.209 | W12: =V12 -> 25407.209
A13: Dallas Fase 2 | B13: 695 Beaumont | C13: 416 | E13: 6 | F13: 2496 | G13: 8.00 X 3.00 | H13: Micros | I13: 43053 | J13: 8 | K13: 6268.32 | L13: 16129 | M13: 13733 | N13: =(L13+M13)/2*1.15 -> 17170.65 | O13: =N13*1.15 -> 19746.247 | P13: =O13 -> 19746.247 | Q13: =P13 -> 19746.247 | R13: =Q13 -> 19746.247 | S13: =R13 -> 19746.247 | T13: =S13 -> 19746.247 | U13: =T13 -> 19746.247 | V13: =U13 -> 19746.247 | W13: =V13 -> 19746.247
A14: Dallas Onder | B14: 695 Beaumont | C14: 307 | D14: 4.39 | E14: 4 | F14: 1228 | G14: 6.50 X 5.00 | H14: Micros | I14: 43053 | J14: 8 | K14: 3507.84 | L14: 16262 | M14: 9379 | N14: =(L14+M14)/2*1.15 -> 14743.575 | O14: =N14*1.15 -> 16955.111 | P14: =O14 -> 16955.111 | Q14: =P14 -> 16955.111 | R14: =Q14 -> 16955.111 | S14: =R14 -> 16955.111 | T14: =S14 -> 16955.111 | U14: =T14 -> 16955.111 | V14: =U14 -> 16955.111 | W14: =V14 -> 16955.111
A15: DM10 | B15: 695 Beaumont | C15: 476 | D15: 2.13 | E15: 2.11 | F15: 1004.36 | G15: 7.00 X 3.00 | H15: Micros | I15: 42313 | J15: 10 | K15: 10240.56 | L15: 10474 | M15: 6605 | N15: =(L15+M15)/2 -> 8539.5 | O15: =N15 -> 8539.5 | P15: =O15 -> 8539.5 | Q15: =P15 -> 8539.5 | R15: =Q15 -> 8539.5 | S15: =R15 -> 8539.5 | T15: =S15 -> 8539.5 | U15: =T15 -> 8539.5 | V15: =U15 -> 8539.5 | W15: =V15 -> 8539.5
A16: DM11 | B16: 695 Beaumont | C16: 476 | E16: 1.7 | F16: 809.2 | G16: 7.00 X 3.00 | H16: Micros | I16: 42313 | J16: 10 | K16: 6130.08 | L16: 5710 | M16: 5301 | N16: =(L16+M16)/2 -> 5505.5 | O16: =N16 -> 5505.5 | P16: =O16 -> 5505.5 | Q16: =P16 -> 5505.5 | R16: =Q16 -> 5505.5 | S16: =R16 -> 5505.5 | T16: =S16 -> 5505.5 | U16: =T16 -> 5505.5 | V16: =U16 -> 5505.5 | W16: =V16 -> 5505.5
A17: DM12 | B17: 695 Beaumont | C17: 476 | E17: 1 | F17: 476 | G17: 7.00 X 3.00 | H17: Micros | I17: 42313 | J17: 10 | K17: 2963.52 | L17: 5724 | M17: 3588 | N17: =(L17+M17)/2 -> 4656 | O17: =N17 -> 4656 | P17: =O17 -> 4656 | Q17: =P17 -> 4656 | R17: =Q17 -> 4656 | S17: =R17 -> 4656 | T17: =S17 -> 4656 | U17: =T17 -> 4656 | V17: =U17 -> 4656 | W17: =V17 -> 4656
A18: DM13 | B18: 695 Beaumont | C18: 476 | E18: 0.83 | F18: 395.08 | G18: 7.00 X 3.00 | H18: Micros | I18: 42313 | J18: 10 | K18: 2423.52 | L18: 3062 | M18: 2175 | N18: =(L18+M18)/2 -> 2618.5 | O18: =N18 -> 2618.5 | P18: =O18 -> 2618.5 | Q18: =P18 -> 2618.5 | R18: =Q18 -> 2618.5 | S18: =R18 -> 2618.5 | T18: =S18 -> 2618.5 | U18: =T18 -> 2618.5 | V18: =U18 -> 2618.5 | W18: =V18 -> 2618.5
A19: DM15 | B19: 695 Beaumont | C19: 476 | E19: 0.3 | F19: 142.8 | G19: 7.00 X 3.00 | H19: Micros | I19: 42313 | J19: 10 | K19: 5002.56 | L19: 6155 | M19: 5171 | N19: =(L19+M19)/2 -> 5663 | O19: =N19 -> 5663 | P19: =O19 -> 5663 | Q19: =P19 -> 5663 | R19: =Q19 -> 5663 | S19: =R19 -> 5663 | T19: =S19 -> 5663 | U19: =T19 -> 5663 | V19: =U19 -> 5663 | W19: =V19 -> 5663
A20: DM16 | B20: 695 Beaumont | C20: 476 | D20: 1.2 | E20: 1.11 | F20: 528.36 | G20: 7.00 X 3.00 | H20: Micros | I20: 42313 | J20: 10
A21: DM19 | B21: 695 Beaumont | C21: 312 | E21: 1.45 | F21: 452.4 | G21: 8.00 X 4.00 | H21: Micros | I21: 42313 | J21: 10 | K21: 13497.84 | L21: 17699 | M21: 14986 | N21: =(L21+M21)/2 -> 16342.5 | O21: =N21 -> 16342.5 | P21: =O21 -> 16342.5 | Q21: =P21 -> 16342.5 | R21: =Q21 -> 16342.5 | S21: =R21 -> 16342.5 | T21: =S21 -> 16342.5 | U21: =T21 -> 16342.5 | V21: =U21 -> 16342.5 | W21: =V21 -> 16342.5
A22: DM20 | B22: 695 Beaumont | C22: 312 | E22: 0.52 | F22: 162.24 | G22: 8.00 X 4.00 | H22: Micros | I22: 42313 | J22: 10
A23: DM21 | B23: 695 Beaumont | C23: 312 | E23: 1.06 | F23: 330.72 | G23: 8.00 X 4.00 | H23: Micros | I23: 42313 | J23: 10
A24: DM22 | B24: 695 Beaumont | C24: 312 | E24: 1.26 | F24: 393.12 | G24: 8.00 X 4.00 | H24: Micros | I24: 42313 | J24: 10
A25: L1 | B25: 695 Beaumont | C25: 416 | E25: 3.76 | F25: 1564.16 | G25: 7.00 X 3.43 | H25: Micros | I25: 44568 | J25: 10 | K25: 42284.16 | L25: 87862 | M25: 71924 | N25: =(L25+M25)/2 -> 79893 | O25: =N25 -> 79893 | P25: =O25 -> 79893 | Q25: =P25 -> 79893 | R25: =Q25 -> 79893 | S25: =R25 -> 79893 | T25: =S25 -> 79893 | U25: =T25 -> 79893 | V25: =U25 -> 79893 | W25: =V25 -> 79893
A26: L2 | B26: 695 Beaumont | C26: 416 | E26: 3.73 | F26: 1551.68 | G26: 7.00 X 3.43 | H26: Micros | I26: 44568 | J26: 10
A27: L3 | B27: 695 Beaumont | C27: 416 | E27: 3.29 | F27: 1368.64 | G27: 7.00 X 3.43 | H27: Micros | I27: 44568 | J27: 10
A28: L4 | B28: 695 Beaumont | C28: 416 | E28: 3.34 | F28: 1389.44 | G28: 7.00 X 3.43 | H28: Micros | I28: 44568 | J28: 10
A29: L5 | B29: 695 Beaumont | C29: 416 | E29: 2.98 | F29: 1239.68 | G29: 7.00 X 3.43 | H29: Micros | I29: 44568 | J29: 10
A30: L6 | B30: 695 Beaumont | C30: 416 | E30: 3.65 | F30: 1518.4 | G30: 7.00 X 3.43 | H30: Micros | I30: 44568 | J30: 10
A31: Plaas 2 nr 1 | B31: 695 Beaumont | C31: 312 | E31: 1.26 | F31: 393.12 | G31: 8.00 X 4.00 | H31: Micros | I31: 42439 | J31: 9 | K31: 5929.2 | L31: 19090 | M31: 7871 | N31: =(L31+M31)/2 -> 13480.5 | O31: =N31 -> 13480.5 | P31: =O31 -> 13480.5 | Q31: =P31 -> 13480.5 | R31: =Q31 -> 13480.5 | S31: =R31 -> 13480.5 | T31: =S31 -> 13480.5 | U31: =T31 -> 13480.5 | V31: =U31 -> 13480.5 | W31: =V31 -> 13480.5
A32: Plaas 2 nr 3 | B32: 695 Beaumont | C32: 312 | E32: 2 | F32: 624 | G32: 8.00 X 4.00 | H32: Micros | I32: 42439 | J32: 9
A33: Plaas 2 nr 5 | B33: 695 Beaumont | C33: 312 | E33: 1.85 | F33: 577.2 | G33: 8.00 X 4.00 | H33: Micros | I33: 42439 | J33: 9
A34: Plaas 2 nr 7 | B34: 695 Beaumont | C34: 312 | E34: 1.82 | F34: 567.84 | G34: 8.00 X 4.00 | H34: Micros | I34: 42439 | J34: 9 | K34: 6847.2 | L34: 15771 | M34: 10809 | N34: =(L34+M34)/2 -> 13290 | O34: =N34 -> 13290 | P34: =O34 -> 13290 | Q34: =P34 -> 13290 | R34: =Q34 -> 13290 | S34: =R34 -> 13290 | T34: =S34 -> 13290 | U34: =T34 -> 13290 | V34: =U34 -> 13290 | W34: =V34 -> 13290
A35: Plaas 2 nr 9 | B35: 695 Beaumont | C35: 312 | E35: 1.65 | F35: 514.8 | G35: 8.00 X 4.00 | H35: Micros | I35: 42439 | J35: 9
A36: Plaas 2 nr 11 | B36: 695 Beaumont | C36: 312 | E36: 0.46 | F36: 143.52 | G36: 8.00 X 4.00 | H36: Micros | I36: 42439 | J36: 9
A37: Plaas 2 nr 13 | B37: 695 Beaumont | C37: 312 | E37: 1.95 | F37: 608.4 | G37: 8.00 X 4.00 | H37: Micros | I37: 42439 | J37: 9 | K37: 38705.04 | L37: 48975 | M37: 30758 | N37: =(L37+M37)/2 -> 39866.5 | O37: =N37 -> 39866.5 | P37: =O37 -> 39866.5 | Q37: =P37 -> 39866.5 | R37: =Q37 -> 39866.5 | S37: =R37 -> 39866.5 | T37: =S37 -> 39866.5 | U37: =T37 -> 39866.5 | V37: =U37 -> 39866.5 | W37: =V37 -> 39866.5
A38: Plaas 2 nr 14 | B38: 695 Beaumont | C38: 312 | E38: 2.27 | F38: 708.24 | G38: 8.00 X 4.00 | H38: Micros | I38: 42439 | J38: 9
A39: Plaas 2 nr 15 | B39: 695 Beaumont | C39: 416 | E39: 2.05 | F39: 852.8 | G39: 8.00 X 3.00 | H39: Micros | I39: 42439 | J39: 9
A40: Plaas 2 nr 16 | B40: 695 Beaumont | C40: 312 | E40: 2.07 | F40: 645.84 | G40: 8.00 X 4.00 | H40: Micros | I40: 42439 | J40: 9
...

Sheet Orchard Analysis
A1: PRODUCTION SUMMARIES HAZYVIEW
A2: Row Labels | B2: Hectares | C2: Sum of DNIS 2023 | D2: Sum of DNIS 2024 | E2: Sum of DNIS 2025 | F2: Sum of 2026 | G2: Sum of 2027 | H2: Sum of 2028 | I2: Sum of 2029 | J2: Sum of 2030 | K2: Sum of 2031 | L2: Sum of 2032 | M2: Sum of 2033 | N2: Sum of 2034 | O2: Sum of 2035
A3: 695 Beaumont | B3: 116.73 | C3: 287781.12 | D3: 473122 | E3: 385560 | F3: 439071.28 | G3: 450261.09 | H3: 450261.09 | I3: 450261.09 | J3: 450261.09 | K3: 450261.09 | L3: 450261.09 | M3: 450261.09 | N3: 450261.09 | O3: 450261.09
A4: 816 | B4: 17.26 | C4: 24987.487 | D4: 57727 | E4: 35067 | F4: 51036.7 | G4: 56140.37 | H4: 61754.407 | I4: 67929.848 | J4: 72835.974 | K4: 72835.974 | L4: 72835.974 | M4: 72835.974 | N4: 72835.974 | O4: 72835.974
A5: A4 | B5: 12 | C5: 4666.6125 | D5: 10736 | E5: 24896 | F5: 37344 | G5: 41078.4 | H5: 45186.24 | I5: 49704.864 | J5: 54675.35 | K5: 60142.885 | L5: 66157.174 | M5: 72772.891 | N5: 72772.891 | O5: 72772.891
A6: Nelmac 2 | B6: 9 | C6: 4843.8 | D6: 16942 | E6: 12481 | F6: 19549.4 | G6: 25625.68 | H6: 30750.816 | I6: 36900.979 | J6: 44281.175 | K6: 53137.41 | L6: 55383.534 | M6: 58078.882 | N6: 58078.882 | O6: 58078.882
A7: (blank)
A8: Grand Total | B8: 154.99 | C8: 322279.02 | D8: 558527 | E8: 458004 | F8: 547001.38 | G8: 573105.54 | H8: 587952.55 | I8: 604796.78 | J8: 622053.59 | K8: 636377.36 | L8: 644637.77 | M8: 653948.84 | N8: 653948.84 | O8: 653948.84
A9: Row Labels | B9: Hectares | C9: Sum of DNIS 2023 | D9: Sum of DNIS 2024 | E9: Sum of DNIS 2025 | F9: Sum of 2026 | G9: Sum of 2027 | H9: Sum of 2028 | I9: Sum of 2029 | J9: Sum of 2030 | K9: Sum of 2031 | L9: Sum of 2032 | M9: Sum of 2033 | N9: Sum of 2034 | O9: Sum of 2035
A10: 695 Beaumont | B10: 116.73 | C10: 287781.12 | D10: 473122 | E10: 385560 | F10: 439071.28 | G10: 450261.09 | H10: 450261.09 | I10: 450261.09 | J10: 450261.09 | K10: 450261.09 | L10: 450261.09 | M10: 450261.09 | N10: 450261.09 | O10: 450261.09
A11: 816 | B11: 17.26 | C11: 24987.487 | D11: 57727 | E11: 35067 | F11: 51036.7 | G11: 56140.37 | H11: 61754.407 | I11: 67929.848 | J11: 72835.974 | K11: 72835.974 | L11: 72835.974 | M11: 72835.974 | N11: 72835.974 | O11: 72835.974
A12: A4 | B12: 12 | C12: 4666.6125 | D12: 10736 | E12: 24896 | F12: 37344 | G12: 41078.4 | H12: 45186.24 | I12: 49704.864 | J12: 54675.35 | K12: 60142.885 | L12: 66157.174 | M12: 72772.891 | N12: 72772.891 | O12: 72772.891
A13: Nelmac 2 | B13: 9 | C13: 4843.8 | D13: 16942 | E13: 12481 | F13: 19549.4 | G13: 25625.68 | H13: 30750.816 | I13: 36900.979 | J13: 44281.175 | K13: 53137.41 | L13: 55383.534 | M13: 58078.882 | N13: 58078.882 | O13: 58078.882
A15: Row Labels | B15: Hectares | C15: AVG 2023 | D15: AVG 2024 | E15: AVG 2025 | F15: AVG 2026 | G15: AVG 2027 | H15: AVG 2028 | I15: AVG 2029 | J15: AVG 2030 | K15: AVG 2031 | L15: AVG 2032 | M15: AVG 2033 | N15: AVG 2034 | O15: AVG 2035
A16: 695 Beaumont | B16: 116.73 | C16: =C10/$B10 -> 2465.357 | D16: =D10/$B10 -> 4053.1312 | E16: =E10/$B10 -> 3303.0069 | F16: =F10/$B10 -> 3761.4262 | G16: =G10/$B10 -> 3857.2868 | H16: =H10/$B10 -> 3857.2868 | I16: =I10/$B10 -> 3857.2868 | J16: =J10/$B10 -> 3857.2868 | ... O16: =O10/$B10 -> 3857.2868
A17: 816 | B17: 17.26 | C17: =C11/$B11 -> 1447.7107 | D17: =D11/$B11 -> 3344.5539 | E17: =E11/$B11 -> 2031.6918 | F17: =F11/$B11 -> 2956.9351 | G17: =G11/$B11 -> 3252.6286 | H17: =H11/$B11 -> 3577.8915 | I17: =I11/$B11 -> 3935.6806 | J17: =J11/$B11 -> 4219.9289 | ... O17: =O11/$B11 -> 4219.9289
A18: A4 | B18: 12 | C18: =C12/$B12 -> 388.88438 | D18: =D12/$B12 -> 894.66667 | E18: =E12/$B12 -> 2074.6667 | F18: =F12/$B12 -> 3112 | G18: =G12/$B12 -> 3423.2 | H18: =H12/$B12 -> 3765.52 | I18: =I12/$B12 -> 4142.072 | J18: =J12/$B12 -> 4556.2792 | ... O18: =O12/$B12 -> 6064.4076
A19: Nelmac 2 | B19: 9 | C19: =C13/$B13 -> 538.2 | D19: =D13/$B13 -> 1882.4444 | E19: =E13/$B13 -> 1386.7778 | F19: =F13/$B13 -> 2172.1556 | G19: =G13/$B13 -> 2847.2978 | H19: =H13/$B13 -> 3416.7573 | I19: =I13/$B13 -> 4100.1088 | J19: =J13/$B13 -> 4920.1306 | ... O19: =O13/$B13 -> 6453.2091
A20: TOTAL AVG T/HA | C20: =AVERAGE(C16:C19) -> 1210.038 | D20: =AVERAGE(D16:D19) -> 2543.699 | E20: =AVERAGE(E16:E19) -> 2199.0358 | F20: =AVERAGE(F16:F19) -> 3000.6292 | G20: =AVERAGE(G16:G19) -> 3345.1033 | H20: =AVERAGE(H16:H19) -> 3654.3639 | I20: =AVERAGE(I16:I19) -> 4008.7871 | J20: =AVERAGE(J16:J19) -> 4388.4064 | ... O20: =AVERAGE(O16:O19) -> 5148.7081
A22: PRODUCTION SUMMARIES BARBERTON
B23: AVG 2026 | C23: AVG 2027 | D23: AVG 2028 | E23: AVG 2029 | F23: AVG 2030
A24: 788 | B24: 2010.6542 | C24: 2010.6542 | D24: 2010.6542 | E24: 2010.6542 | F24: 2010.6542
A25: 814 | B25: 2765.5493 | C25: 2991.1328 | D25: 3239.2747 | E25: 3512.2307 | F25: 3812.4824
A26: 816 | B26: 3416.9764 | C26: 3630.1582 | D26: 3864.6582 | E26: 4122.6081 | F26: 4406.353
A27: A16 | B27: 2265.978 | C27: 2492.5758 | D27: 2741.8334 | E27: 2741.8334 | F27: 2741.8334
A28: A4 | B28: 2152.2816 | C28: 2346.0261 | D28: 2559.145 | E28: 2676.4337 | F28: 2805.4511
A29: BMT | B29: 3355.9821 | C29: 3660.2369 | D29: 3690.4499 | E29: 3690.4499 | F29: 3690.4499
A30: DAD | B30: 3000 | C30: 3000 | D30: 3000 | E30: 3000 | F30: 3000
A31: MIX | B31: 2200 | C31: 2200 | D31: 2200 | E31: 2200 | F31: 2200
A32: TOTAL AVG | B32: 2645.9277 | C32: 2791.348 | D32: 2913.2519 | E32: 2994.2763 | F32: 3083.403
A34: Row Labels | B34: Sum of ha | C34: Sum of 2026 | D34: Sum of 2027 | E34: Sum of 2028 | F34: Sum of 2029 | G34: Sum of 2030
A35: 788 | B35: 10.7 | C35: 21514 | D35: 21514 | E35: 21514 | F35: 21514 | G35: 21514
A36: 814 | B36: 21 | C36: 58076.536 | D36: 62813.79 | E36: 68024.769 | F36: 73756.846 | G36: 80062.13
A37: 816 | B37: 25.2 | C37: 86107.806 | D37: 91479.987 | E37: 97389.386 | F37: 103889.72 | G37: 111040.1
A38: A16 | B38: 1.4 | C38: 3172.3692 | D38: 3489.6061 | E38: 3838.5667 | F38: 3838.5667 | G38: 3838.5667
A39: A4 | B39: 16.85 | C39: 36265.945 | D39: 39530.54 | E39: 43121.594 | F39: 45097.907 | G39: 47271.852
A40: BMT | B40: 45.5 | C40: 152697.19 | D40: 166540.78 | E40: 167915.47 | F40: 167915.47 | G40: 167915.47
A41: DAD | B41: 1.4 | C41: 4200 | D41: 4200 | E41: 4200 | F41: 4200 | G41: 4200
A42: MIX | B42: 0.3 | C42: 660 | D42: 660 | E42: 660 | F42: 660 | G42: 660
A43: Grand Total | B43: 122.35 | C43: 362693.84 | D43: 390228.7 | E43: 406663.79 | F43: 420872.52 | G43: 436502.12

Sheet capex
A1: CAPITAL EXPENDITURE
A2: CAPEX OVERVIEW | B2: R (*1000)
A3: Net purchase price | B3: 80000 | C3: =B3/Parameters!$B$2 -> 4166.6667
A4: Working capital (10m opex) | B4: ='P&L'!B47/12*10 -> 10267.469 | C4: =B4/Parameters!$B$2 -> 534.76402
A5: transaction, commissions & financing cost | B5: 3000 | C5: =B5/Parameters!$B$2 -> 156.25
A6: buffer (general/ Busdev/ Transition cost) | B6: 0 | C6: =B6/Parameters!$B$2 -> 0
A9: TOTAL | B9: =SUM(B3:B8) -> 93267.469 | C9: =SUM(C3:C8) -> 4857.6807
A11: benefits hazyview | B11: - new solar system at the process of being commissioned (grid independence/ cost reduction)
B12: - new machinery/ equipment
B13: - tourism potential next to kruger / on main road from Joburg
B14: - best quality/ most vertile of land (highest yields/ enough water/ less prowned to hail)
B15: - new solar system to be commissioned
B16: - on site manager/ stay on with good reputation
B17: - well located (accessible and transport efficiencies)

Sheet P&L
A1: PROFIT & LOSS, CASHFLOW & ENTERPRISE VALUE (*1000)
A2: PRODUCTION INCOME | B2: 2026 | C2: 2027 | D2: 2028 | E2: 2029 | F2: 2030 | G2: 2031
A3: ='Orchard Analysis'!A3 -> 695 Beaumont | B3: =GETPIVOTDATA("Sum of 2026",'Orchard Analysis'!$A$2,"Cultivar","695 Beaumont") -> 439071.28 | C3: =GETPIVOTDATA("Sum of 2027",'Orchard Analysis'!$A$2,"Cultivar","695 Beaumont") -> 450261.09 | D3: =GETPIVOTDATA("Sum of 2028",'Orchard Analysis'!$A$2,"Cultivar","695 Beaumont") -> 450261.09 | E3: =GETPIVOTDATA("Sum of 2029",'Orchard Analysis'!$A$2,"Cultivar","695 Beaumont") -> 450261.09 | F3: =GETPIVOTDATA("Sum of 2030",'Orchard Analysis'!$A$2,"Cultivar","695 Beaumont") -> 450261.09 | G3: =GETPIVOTDATA("Sum of 2031",'Orchard Analysis'!$A$2,"Cultivar","695 Beaumont") -> 450261.09
A4: ='Orchard Analysis'!A4 -> 816 | B4: =GETPIVOTDATA("Sum of 2026",'Orchard Analysis'!$A$2,"Cultivar","816") -> 51036.7 | C4: =GETPIVOTDATA("Sum of 2027",'Orchard Analysis'!$A$2,"Cultivar","816") -> 56140.37 | D4: =GETPIVOTDATA("Sum of 2028",'Orchard Analysis'!$A$2,"Cultivar","816") -> 61754.407 | E4: =GETPIVOTDATA("Sum of 2029",'Orchard Analysis'!$A$2,"Cultivar","816") -> 67929.848 | F4: =GETPIVOTDATA("Sum of 2030",'Orchard Analysis'!$A$2,"Cultivar","816") -> 72835.974 | G4: =GETPIVOTDATA("Sum of 2031",'Orchard Analysis'!$A$2,"Cultivar","816") -> 72835.974
A5: ='Orchard Analysis'!A5 -> A4 | B5: =GETPIVOTDATA("Sum of 2026",'Orchard Analysis'!$A$2,"Cultivar","A4") -> 37344 | C5: =GETPIVOTDATA("Sum of 2027",'Orchard Analysis'!$A$2,"Cultivar","A4") -> 41078.4 | D5: =GETPIVOTDATA("Sum of 2028",'Orchard Analysis'!$A$2,"Cultivar","A4") -> 45186.24 | E5: =GETPIVOTDATA("Sum of 2029",'Orchard Analysis'!$A$2,"Cultivar","A4") -> 49704.864 | F5: =GETPIVOTDATA("Sum of 2030",'Orchard Analysis'!$A$2,"Cultivar","A4") -> 54675.35 | G5: =GETPIVOTDATA("Sum of 2031",'Orchard Analysis'!$A$2,"Cultivar","A4") -> 60142.885
A6: ='Orchard Analysis'!A6 -> Nelmac 2 | B6: =GETPIVOTDATA("Sum of 2026",'Orchard Analysis'!$A$2,"Cultivar","Nelmac 2") -> 19549.4 | C6: =GETPIVOTDATA("Sum of 2027",'Orchard Analysis'!$A$2,"Cultivar","Nelmac 2") -> 25625.68 | D6: =GETPIVOTDATA("Sum of 2028",'Orchard Analysis'!$A$2,"Cultivar","Nelmac 2") -> 30750.816 | E6: =GETPIVOTDATA("Sum of 2029",'Orchard Analysis'!$A$2,"Cultivar","Nelmac 2") -> 36900.979 | F6: =GETPIVOTDATA("Sum of 2030",'Orchard Analysis'!$A$2,"Cultivar","Nelmac 2") -> 44281.175 | G6: =GETPIVOTDATA("Sum of 2031",'Orchard Analysis'!$A$2,"Cultivar","Nelmac 2") -> 53137.41
A7: TOTAL tonnes | B7: =SUM(B3:B6) -> 547001.38 | C7: =SUM(C3:C6) -> 573105.54 | D7: =SUM(D3:D6) -> 587952.55 | E7: =SUM(E3:E6) -> 604796.78 | F7: =SUM(F3:F6) -> 622053.59 | G7: =SUM(G3:G6) -> 636377.36
A9: Price KG
A10: =A3 -> 695 Beaumont | B10: =Parameters!B14 -> 48 | C10: =B10+B10*Parameters!$B$3 -> 49.92 | D10: =C10+C10*Parameters!$B$3 -> 51.9168 | E10: =D10+D10*Parameters!$B$3 -> 53.993472 | F10: =E10+E10*Parameters!$B$3 -> 56.153211 | G10: =F10+F10*Parameters!$B$3 -> 58.399339
A11: =A4 -> 816 | B11: =Parameters!B15 -> 61.5 | C11: =B11+B11*Parameters!$B$3 -> 63.96 | D11: =C11+C11*Parameters!$B$3 -> 66.5184 | E11: =D11+D11*Parameters!$B$3 -> 69.179136 | F11: =E11+E11*Parameters!$B$3 -> 71.946301 | G11: =F11+F11*Parameters!$B$3 -> 74.824153
A12: =A5 -> A4 | B12: =Parameters!B16 -> 59.5 | C12: =B12+B12*Parameters!$B$3 -> 61.88 | D12: =C12+C12*Parameters!$B$3 -> 64.3552 | E12: =D12+D12*Parameters!$B$3 -> 66.929408 | F12: =E12+E12*Parameters!$B$3 -> 69.606584 | G12: =F12+F12*Parameters!$B$3 -> 72.390848
A13: =A6 -> Nelmac 2 | B13: =Parameters!B17 -> 49.5 | C13: =B13+B13*Parameters!$B$3 -> 51.48 | D13: =C13+C13*Parameters!$B$3 -> 53.5392 | E13: =D13+D13*Parameters!$B$3 -> 55.680768 | F13: =E13+E13*Parameters!$B$3 -> 57.907999 | G13: =F13+F13*Parameters!$B$3 -> 60.224319
A15: INCOME
A16: =A10 -> 695 Beaumont | B16: =(B3*B10)/1000 -> 21075.421 | C16: =(C3*C10)/1000 -> 22477.034 | D16: =(D3*D10)/1000 -> 23376.115 | E16: =(E3*E10)/1000 -> 24311.16 | F16: =(F3*F10)/1000 -> 25283.606 | G16: =(G3*G10)/1000 -> 26294.95
A17: =A11 -> 816 | B17: =(B4*B11)/1000 -> 3138.757 | C17: =(C4*C11)/1000 -> 3590.7381 | D17: =(D4*D11)/1000 -> 4107.8043 | E17: =(E4*E11)/1000 -> 4699.3282 | F17: =(F4*F11)/1000 -> 5240.2789 | G17: =(G4*G11)/1000 -> 5449.8901
A18: =A12 -> A4 | B18: =(B5*B12)/1000 -> 2221.968 | C18: =(C5*C12)/1000 -> 2541.9314 | D18: =(D5*D12)/1000 -> 2907.9695 | E18: =(E5*E12)/1000 -> 3326.7171 | F18: =(F5*F12)/1000 -> 3805.7644 | G18: =(G5*G12)/1000 -> 4353.7945
A19: =A13 -> Nelmac 2 | B19: =(B6*B13)/1000 -> 967.6953 | C19: =(C6*C13)/1000 -> 1319.21 | D19: =(D6*D13)/1000 -> 1646.3741 | E19: =(E6*E13)/1000 -> 2054.6749 | F19: =(F6*F13)/1000 -> 2564.2342 | G19: =(G6*G13)/1000 -> 3200.1643
A20: TOTAL INCOME | B20: =SUM(B16:B19) -> 27403.842 | C20: =SUM(C16:C19) -> 29928.913 | D20: =SUM(D16:D19) -> 32038.263 | E20: =SUM(E16:E19) -> 34391.88 | F20: =SUM(F16:F19) -> 36893.884 | G20: =SUM(G16:G19) -> 39298.799
A22: COST | B22: 2026 | C22: 2027 | D22: 2028 | E22: 2029 | F22: 2030 | G22: 2031
A23: Bank Fees | B23: 83.964982 | C23: =B23+(B23*Parameters!$B$3) -> 87.323582 | D23: =C23+(C23*Parameters!$B$3) -> 90.816525 | E23: =D23+(D23*Parameters!$B$3) -> 94.449186 | F23: =E23+(E23*Parameters!$B$3) -> 98.227153 | G23: =F23+(F23*Parameters!$B$3) -> 102.15624
A24: Bees | B24: 67.6 | C24: =B24+(B24*Parameters!$B$3) -> 70.304 | D24: =C24+(C24*Parameters!$B$3) -> 73.11616 | E24: =D24+(D24*Parameters!$B$3) -> 76.040806 | F24: =E24+(E24*Parameters!$B$3) -> 79.082439 | G24: =F24+(F24*Parameters!$B$3) -> 82.245736
A25: Diesel | B25: 1013.2533 | C25: =B25+(B25*Parameters!$B$3) -> 1053.7834 | D25: =C25+(C25*Parameters!$B$3) -> 1095.9348 | E25: =D25+(D25*Parameters!$B$3) -> 1139.7722 | F25: =E25+(E25*Parameters!$B$3) -> 1185.3631 | G25: =F25+(F25*Parameters!$B$3) -> 1232.7776
A26: Chemicals | B26: 1297.9148 | C26: =B26+(B26*Parameters!$B$3) -> 1349.8314 | D26: =C26+(C26*Parameters!$B$3) -> 1403.8246 | E26: =D26+(D26*Parameters!$B$3) -> 1459.9776 | F26: =E26+(E26*Parameters!$B$3) -> 1518.3767 | G26: =F26+(F26*Parameters!$B$3) -> 1579.1118
A27: Fertilizer | B27: 1397.5528 | C27: =B27+(B27*Parameters!$B$3) -> 1453.4549 | D27: =C27+(C27*Parameters!$B$3) -> 1511.5931 | E27: =D27+(D27*Parameters!$B$3) -> 1572.0569 | F27: =E27+(E27*Parameters!$B$3) -> 1634.9391 | G27: =F27+(F27*Parameters!$B$3) -> 1700.3367
A28: General Expenses | B28: 84.778314 | C28: =B28+(B28*Parameters!$B$3) -> 88.169447 | D28: =C28+(C28*Parameters!$B$3) -> 91.696225 | E28: =D28+(D28*Parameters!$B$3) -> 95.364074 | F28: =E28+(E28*Parameters!$B$3) -> 99.178637 | G28: =F28+(F28*Parameters!$B$3) -> 103.14578
A29: Konsultasie fooie | B29: 42.15977 | C29: =B29+(B29*Parameters!$B$3) -> 43.84616 | D29: =C29+(C29*Parameters!$B$3) -> 45.600007 | E29: =D29+(D29*Parameters!$B$3) -> 47.424007 | F29: =E29+(E29*Parameters!$B$3) -> 49.320967 | G29: =F29+(F29*Parameters!$B$3) -> 51.293806
A30: Levies | B30: 96.813714 | C30: =B30+(B30*Parameters!$B$3) -> 100.68626 | D30: =C30+(C30*Parameters!$B$3) -> 104.71371 | E30: =D30+(D30*Parameters!$B$3) -> 108.90226 | F30: =E30+(E30*Parameters!$B$3) -> 113.25835 | G30: =F30+(F30*Parameters!$B$3) -> 117.78869
A31: Licenses | B31: 32.995664 | C31: =B31+(B31*Parameters!$B$3) -> 34.315491 | D31: =C31+(C31*Parameters!$B$3) -> 35.68811 | E31: =D31+(D31*Parameters!$B$3) -> 37.115635 | F31: =E31+(E31*Parameters!$B$3) -> 38.60026 | G31: =F31+(F31*Parameters!$B$3) -> 40.14427
A32: Repairs & Maintenance | B32: 589.59862 | C32: =B32+(B32*Parameters!$B$3) -> 613.18256 | D32: =C32+(C32*Parameters!$B$3) -> 637.70987 | E32: =D32+(D32*Parameters!$B$3) -> 663.21826 | F32: =E32+(E32*Parameters!$B$3) -> 689.74699 | G32: =F32+(F32*Parameters!$B$3) -> 717.33687
A33: Ouditeursfooie | B33: 74.547824 | C33: =B33+(B33*Parameters!$B$3) -> 77.529737 | D33: =C33+(C33*Parameters!$B$3) -> 80.630926 | E33: =D33+(D33*Parameters!$B$3) -> 83.856163 | F33: =E33+(E33*Parameters!$B$3) -> 87.21041 | G33: =F33+(F33*Parameters!$B$3) -> 90.698826
A34: Printing & Stationery | B34: 1.356524 | C34: =B34+(B34*Parameters!$B$3) -> 1.410785 | D34: =C34+(C34*Parameters!$B$3) -> 1.4672164 | E34: =D34+(D34*Parameters!$B$3) -> 1.525905 | F34: =E34+(E34*Parameters!$B$3) -> 1.5869412 | G34: =F34+(F34*Parameters!$B$3) -> 1.6504189
... A46: Expected saving due to new solar | B46: -624 | C46: =B46+(B46*Parameters!$B$3) -> -648.96 | D46: =C46+(C46*Parameters!$B$3) -> -674.9184 | E46: =D46+(D46*Parameters!$B$3) -> -701.91514 | F46: =E46+(E46*Parameters!$B$3) -> -729.99174 | G46: =F46+(F46*Parameters!$B$3) -> -759.19141
A47: TOTAL COST | B47: =SUM(B23:B46) -> 12320.963 | C47: =SUM(C23:C46) -> 12813.801 | D47: =SUM(D23:D46) -> 13326.354 | E47: =SUM(E23:E46) -> 13859.408 | F47: =SUM(F23:F46) -> 14413.784 | G47: =SUM(G23:G46) -> 14990.335
A49: OPEX (cost/ Ha multiplied) | B49: =(Parameters!B9*Parameters!B10)/1000 -> 10850 | C49: =B49+(B49*Parameters!$B$3) -> 11284 | D49: =C49+(C49*Parameters!$B$3) -> 11735.36 | E49: =D49+(D49*Parameters!$B$3) -> 12204.774 | F49: =E49+(E49*Parameters!$B$3) -> 12692.965 | G49: =F49+(F49*Parameters!$B$3) -> 13200.684
A51: EBITDA | B51: =B20-B47 -> 15082.879 | C51: =C20-C47 -> 17115.112 | D51: =D20-D47 -> 18711.909 | E51: =E20-E47 -> 20532.472 | F51: =F20-F47 -> 22480.1 | G51: =G20-G47 -> 24308.464
A52: bank loan interest | B52: =('capital structure'!B5*'capital structure'!D5)/12 -> 333.33333 | C52: =('capital structure'!B5*'capital structure'!D5)/12 -> 333.33333 | D52: =(C63*'capital structure'!$D$5)/12 -> 333.33333 | E52: =(D63*'capital structure'!$D$5)/12 -> 250 | F52: =(E63*'capital structure'!$D$5)/12 -> 166.66667 | G52: =(F63*'capital structure'!$D$5)/12 -> 83.333333
A53: investor loan interest | B53: =B62*'capital structure'!$D$9 -> 0 | C53: =C62*'capital structure'!$D$9 -> 0 | D53: =D62*'capital structure'!$D$9 -> 0 | E53: =E62*'capital structure'!$D$9 -> 0 | F53: =F62*'capital structure'!$D$9 -> 0 | G53: =G62*'capital structure'!$D$9 -> 0
A54: vendor loan interest
A55: Profit before TAX | B55: =B51-B52-B53 -> 14749.545 | C55: =C51-C52-C53 -> 16781.778 | D55: =D51-D52-D53 -> 18378.576 | E55: =E51-E52-E53 -> 20282.472 | F55: =F51-F52-F53 -> 22313.433 | G55: =G51-G52-G53 -> 24225.13
A56: tax | B56: =B55*Parameters!$B$4 -> 3687.3863 | C56: =C55*Parameters!$B$4 -> 4195.4446 | D56: =D55*Parameters!$B$4 -> 4594.644 | E56: =E55*Parameters!$B$4 -> 5070.618 | F56: =F55*Parameters!$B$4 -> 5578.3582 | G56: =G55*Parameters!$B$4 -> 6056.2826
...

Sheet capital structure
A1: CAPITAL STRUCTURE
B2: (R*1000) | C2: E(*1000) | D2: interest | E2: repayment
A3: Total funding required | B3: =capex!B9 -> 93267.469 | C3: =B3/Parameters!$B$2 -> 4857.6807
A4: 1y interest free vendor loan | B4: 20000 | C4: =B4/Parameters!$B$2 -> 1041.6667 | D4: 0
A5: Bank loan | B5: 40000 | C5: =B5/Parameters!$B$2 -> 2083.3333 | D5: 0.1 | E5: 0.25 | F5: (can be a 10 year repayment)
A7: Total shareholders Capital required | B7: =B3-B4-B5 -> 33267.469 | C7: =B7/Parameters!$B$2 -> 1732.6807
A8: Class B - Cumpref shares | B8: =F8*B7 -> 8316.8673 | F8: 0.25
A9: External investors - Cumprefs (6%) | B9: =F8*B7 -> 8316.8673 | C9: =B9/Parameters!$B$2 -> 433.17017
A11: Class A - Ordinary shares | B11: =B7-B8 -> 24950.602 | F11: =100%-F8 -> 0.75
A12: External investors - normal shares | B12: =B11*E12 -> 6237.6505 | C12: =B12/Parameters!$B$2 -> 324.87763 | E12: =100%-E13-E14 -> 0.25
A13: MBI | B13: =B11*E13 -> 2495.0602 | C13: =B13/Parameters!$B$2 -> 129.95105 | E13: 0.1
A14: BFC | B14: =E14*B11 -> 16217.891 | C14: =B14/Parameters!$B$2 -> 844.68183 | E14: 0.65
E15: =SUM(E12:E14) -> 1

Sheet Returns
A1: INVESTOR RETURNS - (SAR*1000) | K1: INVESTOR RETURNS - (EUR*1000) | U1: INVESTOR PERFORMANCE
A2: Equity Value | B2: Stake | C2: amount | D2: Y1 | E2: Y2 | F2: Y3 | G2: Y4 | H2: Y5 | I2: Y6 | K2: =A2 -> Equity Value | L2: =B2 -> Stake | M2: =C2 -> amount | N2: =D2 -> Y1 | O2: =E2 -> Y2 | P2: =F2 -> Y3 | Q2: =G2 -> Y4 | R2: =H2 -> Y5 | S2: =I2 -> Y6 | W2: Initial | X2: =N2 -> Y1 | Y2: =O2 -> Y2 | Z2: =P2 -> Y3 | AA2: =Q2 -> Y4 | AB2: =R2 -> Y5 | AC2: =S2 -> Y6
A3: ='capital structure'!A14 -> BFC | B3: ='capital structure'!E14 -> 0.65 | C3: ='capital structure'!B14 -> 16217.891 | D3: =$B3*'P&L'!B$68 -> 18034.44 | E3: =$B3*'P&L'!C$68 -> 28425.557 | F3: =$B3*'P&L'!D$68 -> 40738.818 | G3: =$B3*'P&L'!E$68 -> 56543.352 | H3: =$B3*'P&L'!F$68 -> 73750.94 | I3: =$B3*'P&L'!G$68 -> 91502.874 | K3: =A3 -> BFC | L3: =B3 -> 0.65 | M3: =C3/Parameters!$B$2 -> 844.68183 | N3: =D3/Parameters!$B$2 -> 939.29373 | O3: =E3/Parameters!$B$2 -> 1480.4977 | P3: =F3/Parameters!$B$2 -> 2121.8134 | Q3: =G3/Parameters!$B$2 -> 2944.9662 | R3: =H3/Parameters!$B$2 -> 3841.1948 | S3: =I3/Parameters!$B$2 -> 4765.7747 | U3: Position value (loan & equity) | W3: =M20*1000 -> 758047.8 | X3: =N20*1000 -> 820427.2 | Y3: =O20*1000 -> 1056132.2 | Z3: =P20*1000 -> 1331994.7 | AA3: =Q20*1000 -> 1679546.7 | AB3: =R20*1000 -> 2057062 | AC3: =S20*1000 -> 2447450.4
A4: ='capital structure'!A13 -> MBI | B4: ='capital structure'!E13 -> 0.1 | C4: ='capital structure'!B13 -> 2495.0602 | D4: =$B4*'P&L'!B$68 -> 2774.5292 | E4: =$B4*'P&L'!C$68 -> 4373.1625 | F4: =$B4*'P&L'!D$68 -> 6267.5105 | G4: =$B4*'P&L'!E$68 -> 8698.9772 | H4: =$B4*'P&L'!F$68 -> 11346.298 | I4: =$B4*'P&L'!G$68 -> 14077.365 | K4: =A4 -> MBI | L4: =B4 -> 0.1 | M4: =C4/Parameters!$B$2 -> 129.95105 | N4: =D4/Parameters!$B$2 -> 144.50673 | O4: =E4/Parameters!$B$2 -> 227.76888 | P4: =F4/Parameters!$B$2 -> 326.43284 | Q4: =G4/Parameters!$B$2 -> 453.07173 | R4: =H4/Parameters!$B$2 -> 590.95304 | S4: =I4/Parameters!$B$2 -> 733.19611 | U4: YoY performance | X4: =X3-W3 -> 62379.401 | Y4: =Y3-X3 -> 235705.01 | Z4: =Z3-Y3 -> 275862.49 | AA4: =AA3-Z3 -> 347551.99 | AB4: =AB3-AA3 -> 377515.32 | AC4: =AC3-AB3 -> 390388.43
A5: ='capital structure'!A12 -> External investors - normal shares | B5: ='capital structure'!E12 -> 0.25 | C5: ='capital structure'!B12 -> 6237.6505 | D5: =$B5*'P&L'!B$68 -> 6936.3229 | E5: =$B5*'P&L'!C$68 -> 10932.906 | F5: =$B5*'P&L'!D$68 -> 15668.776 | G5: =$B5*'P&L'!E$68 -> 21747.443 | H5: =$B5*'P&L'!F$68 -> 28365.746 | I5: =$B5*'P&L'!G$68 -> 35193.413 | K5: =A5 -> External investors - normal shares | L5: =B5 -> 0.25 | M5: =C5/Parameters!$B$2 -> 324.87763 | N5: =D5/Parameters!$B$2 -> 361.26682 | O5: =E5/Parameters!$B$2 -> 569.42221 | P5: =F5/Parameters!$B$2 -> 816.08209 | Q5: =G5/Parameters!$B$2 -> 1132.6793 | R5: =H5/Parameters!$B$2 -> 1477.3826 | S5: =I5/Parameters!$B$2 -> 1832.9903 | U5: IRR | X5: =N35 -> 0.082289532 | Y5: =O35 -> 0.18008241 | Z5: =P35 -> 0.20650052 | AA5: =Q35 -> 0.21987337 | AB5: =R35 -> 0.22085102 | AC5: =S35 -> 0.21551078
U6: Money multiple | X6: =N40 -> 1.0822895 | Y6: =O40 -> 1.3932264 | Z6: =P40 -> 1.7571381 | AA6: =Q40 -> 2.2156211 | AB6: =R40 -> 2.713631 | AC6: =S40 -> 3.2286228
A7: Equity appreciation | B7: Stake | C7: amount | D7: Y1 | E7: Y2 | F7: Y3 | G7: Y4 | H7: Y5 | I7: Y6 | K7: =A7 -> Equity appreciation | L7: =B7 -> Stake | M7: =C7 -> amount | N7: =D7 -> Y1 | O7: =E7 -> Y2 | P7: =F7 -> Y3 | Q7: =G7 -> Y4 | R7: =H7 -> Y5 | S7: =I7 -> Y6 | U7: * case is based on continuation & performance of existing operations - not factoring in any BFC upside/ additional revenue
A8: =A3 -> BFC | B8: =B3 -> 0.65 | C8: =C3 -> 16217.891 | D8: =D3-C8 -> 1816.5484 | E8: =E3-(C8+D8) -> 10391.117 | F8: =F3-(C8+D8+E8) -> 12313.262 | G8: =G3-(C8+D8+E8+F8) -> 15804.534 | H8: =H3-(C8+D8+E8+F8+G8) -> 17207.588 | I8: =I3-(C8+D8+E8+F8+G8+H8) -> 17751.935 | K8: =A8 -> BFC | L8: =B8 -> 0.65 | M8: =C8/Parameters!$B$2 -> 844.68183 | N8: =D8/Parameters!$B$2 -> 94.611895 | O8: =E8/Parameters!$B$2 -> 541.20401 | P8: =F8/Parameters!$B$2 -> 641.31571 | Q8: =G8/Parameters!$B$2 -> 823.1528 | R8: =H8/Parameters!$B$2 -> 896.22853 | S8: =I8/Parameters!$B$2 -> 924.57993
A9: =A4 -> MBI | B9: =B4 -> 0.1 | C9: =C4 -> 2495.0602 | D9: =D4-C9 -> 279.46898 | E9: =E4-(C9+D9) -> 1598.6334 | F9: =F4-(C9+D9+E9) -> 1894.3479 | G9: =G4-(C9+D9+E9+F9) -> 2431.4667 | H9: =H4-(C9+D9+E9+F9+G9) -> 2647.3212 | I9: =I4-(C9+D9+E9+F9+G9+H9) -> 2731.0669 | K9: =A9 -> MBI | L9: =B9 -> 0.1 | M9: =C9/Parameters!$B$2 -> 129.95105 | N9: =D9/Parameters!$B$2 -> 14.555676 | O9: =E9/Parameters!$B$2 -> 83.262155 | P9: =F9/Parameters!$B$2 -> 98.663955 | Q9: =G9/Parameters!$B$2 -> 126.63889 | R9: =H9/Parameters!$B$2 -> 137.88131 | S9: =I9/Parameters!$B$2 -> 142.24307
A10: =A5 -> External investors - normal shares | B10: =B5 -> 0.25 | C10: =C5 -> 6237.6505 | D10: =D5-C10 -> 698.67246 | E10: =E5-(C10+D10) -> 3996.5834 | F10: =F5-(C10+D10+E10) -> 4735.8698 | G10: =G5-(C10+D10+E10+F10) -> 6078.6669 | H10: =H5-(C10+D10+E10+F10+G10) -> 6618.303 | I10: =I5-(C10+D10+E10+F10+G10+H10) -> 6827.6672 | K10: =A10 -> External investors - normal shares | L10: =B10 -> 0.25 | M10: =C10/Parameters!$B$2 -> 324.87763 | N10: =D10/Parameters!$B$2 -> 36.38919 | O10: =E10/Parameters!$B$2 -> 208.15539 | P10: =F10/Parameters!$B$2 -> 246.65989 | Q10: =G10/Parameters!$B$2 -> 316.59723 | R10: =H10/Parameters!$B$2 -> 344.70328 | S10: =I10/Parameters!$B$2 -> 355.60767
A12: Loan Value | B12: Interest | C12: amount | D12: Y1 | E12: Y2 | F12: Y3 | G12: Y4 | H12: Y5 | I12: Y6 | K12: =A12 -> Loan Value | L12: =B12 -> Interest | M12: =C12 -> amount | N12: =D12 -> Y1 | O12: =E12 -> Y2 | P12: =F12 -> Y3 | Q12: =G12 -> Y4 | R12: =H12 -> Y5 | S12: =I12 -> Y6
A13: =A3 -> BFC | C13: 0 | D13: =C13 -> 0 | E13: =D13 -> 0 | F13: =E13 -> 0 | G13: =F13 -> 0 | H13: =G13 -> 0 | I13: =H13 -> 0 | K13: =A13 -> BFC | M13: =C13/Parameters!$B$2 -> 0 | N13: =D13/Parameters!$B$2 -> 0 | O13: =E13/Parameters!$B$2 -> 0 | P13: =F13/Parameters!$B$2 -> 0 | Q13: =G13/Parameters!$B$2 -> 0 | R13: =H13/Parameters!$B$2 -> 0 | S13: =I13/Parameters!$B$2 -> 0
A14: =A4 -> MBI | C14: 0 | D14: =C14 -> 0 | E14: =D14 -> 0 | F14: =E14 -> 0 | G14: =F14 -> 0 | H14: =G14 -> 0 | I14: =H14 -> 0 | K14: =A14 -> MBI | M14: =C14/Parameters!$B$2 -> 0 | N14: =D14/Parameters!$B$2 -> 0 | O14: =E14/Parameters!$B$2 -> 0 | P14: =F14/Parameters!$B$2 -> 0 | Q14: =G14/Parameters!$B$2 -> 0 | R14: =H14/Parameters!$B$2 -> 0 | S14: =I14/Parameters!$B$2 -> 0
A15: ='capital structure'!A9 -> External investors - Cumprefs (6%) | B15: =Parameters!B7 -> 0.06 | C15: ='capital structure'!B9 -> 8316.8673 | D15: =C15+(C15*$B$15) -> 8815.8793 | E15: =D15+(D15*$B$15) -> 9344.8321 | F15: =E15+(E15*$B$15) -> 9905.522 | G15: =F15+(F15*$B$15) -> 10499.853 | H15: =G15+(G15*$B$15) -> 11129.845 | I15: =H15+(H15*$B$15) -> 11797.635 | K15: =A15 -> External investors - Cumprefs (6%) | L15: =B15 -> 0.06 | M15: =C15/Parameters!$B$2 -> 433.17017 | N15: =D15/Parameters!$B$2 -> 459.16038 | O15: =E15/Parameters!$B$2 -> 486.71 | P15: =F15/Parameters!$B$2 -> 515.9126 | Q15: =G15/Parameters!$B$2 -> 546.86736 | R15: =H15/Parameters!$B$2 -> 579.6794 | S15: =I15/Parameters!$B$2 -> 614.46017
A17: Total Value | C17: amount | D17: Y1 | E17: Y2 | F17: Y3 | G17: Y4 | H17: Y5 | I17: Y6 | K17: =A17 -> Total Value | M17: =C17 -> amount | N17: =D17 -> Y1 | O17: =E17 -> Y2 | P17: =F17 -> Y3 | Q17: =G17 -> Y4 | R17: =H17 -> Y5 | S17: =I17 -> Y6
A18: =A3 -> BFC | C18: =C3+C13 -> 16217.891 | D18: =D13+D3 -> 18034.44 | E18: =E13+E3 -> 28425.557 | F18: =F13+F3 -> 40738.818 | G18: =G13+G3 -> 56543.352 | H18: =H13+H3 -> 73750.94 | I18: =I13+I3 -> 91502.874 | K18: =A18 -> BFC | M18: =C18/Parameters!$B$2 -> 844.68183 | N18: =D18/Parameters!$B$2 -> 939.29373 | O18: =E18/Parameters!$B$2 -> 1480.4977 | P18: =F18/Parameters!$B$2 -> 2121.8134 | Q18: =G18/Parameters!$B$2 -> 2944.9662 | R18: =H18/Parameters!$B$2 -> 3841.1948 | S18: =I18/Parameters!$B$2 -> 4765.7747
A19: =A4 -> MBI | C19: =C4+C14 -> 2495.0602 | D19: =D14+D4 -> 2774.5292 | E19: =E14+E4 -> 4373.1625 | F19: =F14+F4 -> 6267.5105 | G19: =G14+G4 -> 8698.9772 | H19: =H14+H4 -> 11346.298 | I19: =I14+I4 -> 14077.365 | K19: =A19 -> MBI | M19: =C19/Parameters!$B$2 -> 129.95105 | N19: =D19/Parameters!$B$2 -> 144.50673 | O19: =E19/Parameters!$B$2 -> 227.76888 | P19: =F19/Parameters!$B$2 -> 326.43284 | Q19: =G19/Parameters!$B$2 -> 453.07173 | R19: =H19/Parameters!$B$2 -> 590.95304 | S19: =I19/Parameters!$B$2 -> 733.19611
A20: =A5 -> External investors - normal shares | C20: =C5+C15 -> 14554.518 | D20: =D15+D5 -> 15752.202 | E20: =E15+E5 -> 20277.738 | F20: =F15+F5 -> 25574.298 | G20: =G15+G5 -> 32247.296 | H20: =H15+H5 -> 39495.591 | I20: =I15+I5 -> 46991.048 | K20: =A20 -> External investors - normal shares | M20: =C20/Parameters!$B$2 -> 758.0478 | N20: =D20/Parameters!$B$2 -> 820.4272 | O20: =E20/Parameters!$B$2 -> 1056.1322 | P20: =F20/Parameters!$B$2 -> 1331.9947 | Q20: =G20/Parameters!$B$2 -> 1679.5467 | R20: =H20/Parameters!$B$2 -> 2057.062 | S20: =I20/Parameters!$B$2 -> 2447.4504
A22: Annual yield | C22: =C2 -> amount | D22: Y1 | E22: Y2 | F22: Y3 | G22: Y4 | H22: Y5 | I22: Y6 | K22: =A22 -> Annual yield | M22: =C22 -> amount | N22: =D22 -> Y1 | O22: =E22 -> Y2 | P22: =F22 -> Y3 | Q22: =G22 -> Y4 | R22: =H22 -> Y5 | S22: =I22 -> Y6
A23: BFC | C23: =C3 -> 16217.891 | D23: =D18-C$18 -> 1816.5484 | E23: =E18-D$18 -> 10391.117 | F23: =F18-E$18 -> 12313.262 | G23: =G18-F$18 -> 15804.534 | H23: =H18-G$18 -> 17207.588 | I23: =I18-H$18 -> 17751.935 | K23: =A23 -> BFC | M23: =C23/Parameters!$B$2 -> 844.68183 | N23: =D23/Parameters!$B$2 -> 94.611895 | O23: =E23/Parameters!$B$2 -> 541.20401 | P23: =F23/Parameters!$B$2 -> 641.31571 | Q23: =G23/Parameters!$B$2 -> 823.1528 | R23: =H23/Parameters!$B$2 -> 896.22853 | S23: =I23/Parameters!$B$2 -> 924.57993
A24: MBI | C24: =C4 -> 2495.0602 | D24: =D19-C$19 -> 279.46898 | E24: =E19-D$19 -> 1598.6334 | F24: =F19-E$19 -> 1894.3479 | G24: =G19-F$19 -> 2431.4667 | H24: =H19-G$19 -> 2647.3212 | I24: =I19-H$19 -> 2731.0669 | K24: =A24 -> MBI | M24: =C24/Parameters!$B$2 -> 129.95105 | N24: =D24/Parameters!$B$2 -> 14.555676 | O24: =E24/Parameters!$B$2 -> 83.262155 | P24: =F24/Parameters!$B$2 -> 98.663955 | Q24: =G24/Parameters!$B$2 -> 126.63889 | R24: =H24/Parameters!$B$2 -> 137.88131 | S24: =I24/Parameters!$B$2 -> 142.24307
A25: =A5 -> External investors - normal shares | C25: =C20 -> 14554.518 | D25: =D20-C$20 -> 1197.6845 | E25: =E20-D$20 -> 4525.5362 | F25: =F20-E$20 -> 5296.5597 | G25: =G20-F$20 -> 6672.9982 | H25: =H20-G$20 -> 7248.2942 | I25: =I20-H$20 -> 7495.4579 | K25: =A25 -> External investors - normal shares | M25: =C25/Parameters!$B$2 -> 758.0478 | N25: =D25/Parameters!$B$2 -> 62.379401 | O25: =E25/Parameters!$B$2 -> 235.70501 | P25: =F25/Parameters!$B$2 -> 275.86249 | Q25: =G25/Parameters!$B$2 -> 347.55199 | R25: =H25/Parameters!$B$2 -> 377.51532 | S25: =I25/Parameters!$B$2 -> 390.38843
A27: Annual ROIC | C27: =C7 -> amount | D27: Y1 | E27: Y2 | F27: Y3 | G27: Y4 | H27: Y5 | I27: Y6 | K27: =A27 -> Annual ROIC | M27: =C27 -> amount | N27: =D27 -> Y1 | O27: =E27 -> Y2 | P27: =F27 -> Y3 | Q27: =G27 -> Y4 | R27: =H27 -> Y5 | S27: =I27 -> Y6
A28: BFC | C28: =C8 -> 16217.891 | D28: =D23/$C28 -> 0.11200891 | E28: =E23/$C28 -> 0.64071936 | F28: =F23/$C28 -> 0.75923937 | G28: =G23/$C28 -> 0.97451226 | H28: =H23/$C28 -> 1.061025 | I28: =I23/$C28 -> 1.0945896 | K28: =A28 -> BFC | M28: =C28/Parameters!$B$2 -> 844.68183 | N28: =D28 -> 0.11200891 | O28: =E28 -> 0.64071936 | P28: =F28 -> 0.75923937 | Q28: =G28 -> 0.97451226 | R28: =H28 -> 1.061025 | S28: =I28 -> 1.0945896
A29: MBI | C29: =C9 -> 2495.0602 | D29: =D24/$C29 -> 0.11200891 | E29: =E24/$C29 -> 0.64071936 | F29: =F24/$C29 -> 0.75923937 | G29: =G24/$C29 -> 0.97451226 | H29: =H24/$C29 -> 1.061025 | I29: =I24/$C29 -> 1.0945896 | K29: =A29 -> MBI | M29: =C29/Parameters!$B$2 -> 129.95105 | N29: =D29 -> 0.11200891 | O29: =E29 -> 0.64071936 | P29: =F29 -> 0.75923937 | Q29: =G29 -> 0.97451226 | R29: =H29 -> 1.061025 | S29: =I29 -> 1.0945896
A30: =A5 -> External investors - normal shares | C30: =C25 -> 14554.518 | D30: =D25/$C30 -> 0.082289535 | E30: =E25/$C30 -> 0.31093687 | F30: =F25/$C30 -> 0.36391173 | G30: =G25/$C30 -> 0.45848295 | H30: =H25/$C30 -> 0.49800992 | I30: =I25/$C30 -> 0.51499184 | K30: =A30 -> External investors - normal shares | M30: =C30/Parameters!$B$2 -> 758.0478 | N30: =D30 -> 0.082289535 | O30: =E30 -> 0.31093687 | P30: =F30 -> 0.36391173 | Q30: =G30 -> 0.45848295 | R30: =H30 -> 0.49800992 | S30: =I30 -> 0.51499184
A32: IRR | C32: =C12 -> amount | D32: Y1 | E32: Y2 | F32: Y3 | G32: Y4 | H32: Y5 | I32: Y6 | K32: =A32 -> IRR | M32: =C32 -> amount | N32: =D32 -> Y1 | O32: =E32 -> Y2 | P32: =F32 -> Y3 | Q32: =G32 -> Y4 | R32: =H32 -> Y5 | S32: =I32 -> Y6
A33: BFC | C33: =C28 -> 16217.891 | D33: =J44 -> 0.11200891 | E33: =J47 -> 0.32339838 | F33: =J50 -> 0.35899029 | G33: =J53 -> 0.3661676 | H33: =J56 -> 0.35357583 | I33: =J59 -> 0.33390773 | K33: =A33 -> BFC | M33: =C33 -> 16217.891 | N33: =D33 -> 0.11200891 | O33: =E33 -> 0.32339838 | P33: =F33 -> 0.35899029 | Q33: =G33 -> 0.3661676 | R33: =H33 -> 0.35357583 | S33: =I33 -> 0.33390773
A34: MBI | C34: =C29 -> 2495.0602 | D34: =J45 -> 0.11200891 | E34: =J48 -> 0.32339838 | F34: =J51 -> 0.35899029 | G34: =J54 -> 0.3661676 | H34: =J57 -> 0.35357583 | I34: =J60 -> 0.33390773 | K34: =A34 -> MBI | M34: =C34 -> 2495.0602 | N34: =D34 -> 0.11200891 | O34: =E34 -> 0.32339838 | P34: =F34 -> 0.35899029 | Q34: =G34 -> 0.3661676 | R34: =H34 -> 0.35357583 | S34: =I34 -> 0.33390773
A35: =A10 -> External investors - normal shares | C35: =C30 -> 14554.518 | D35: =J46 -> 0.082289532 | E35: =J49 -> 0.18008241 | F35: =J52 -> 0.20650052 | G35: =J55 -> 0.21987337 | H35: =J58 -> 0.22085102 | I35: =J61 -> 0.21551078 | K35: =A35 -> External investors - normal shares | M35: =C35 -> 14554.518 | N35: =D35 -> 0.082289532 | O35: =E35 -> 0.18008241 | P35: =F35 -> 0.20650052 | Q35: =G35 -> 0.21987337 | R35: =H35 -> 0.22085102 | S35: =I35 -> 0.21551078
A37: Money multiple | D37: Y1 | E37: Y2 | F37: Y3 | G37: Y4 | H37: Y5 | I37: Y6 | K37: =A37 -> Money multiple | N37: =D37 -> Y1 | O37: =E37 -> Y2 | P37: =F37 -> Y3 | Q37: =G37 -> Y4 | R37: =H37 -> Y5 | S37: =I37 -> Y6
A38: =A18 -> BFC | D38: =D18/$C18 -> 1.1120089 | E38: =E18/$C18 -> 1.7527283 | F38: =F18/$C18 -> 2.5119677 | G38: =G18/$C18 -> 3.4864799 | H38: =H18/$C18 -> 4.5475049 | I38: =I18/$C18 -> 5.6420945 | K38: =A38 -> BFC | N38: =D38 -> 1.1120089 | O38: =E38 -> 1.7527283 | P38: =F38 -> 2.5119677 | Q38: =G38 -> 3.4864799 | R38: =H38 -> 4.5475049 | S38: =I38 -> 5.6420945
A39: =A19 -> MBI | D39: =D19/$C19 -> 1.1120089 | E39: =E19/$C19 -> 1.7527283 | F39: =F19/$C19 -> 2.5119677 | G39: =G19/$C19 -> 3.4864799 | H39: =H19/$C19 -> 4.5475049 | I39: =I19/$C19 -> 5.6420945 | K39: =A39 -> MBI | N39: =D39 -> 1.1120089 | O39: =E39 -> 1.7527283 | P39: =F39 -> 2.5119677 | Q39: =G39 -> 3.4864799 | R39: =H39 -> 4.5475049 | S39: =I39 -> 5.6420945
A40: =A20 -> External investors - normal shares | D40: =D20/$C20 -> 1.0822895 | E40: =E20/$C20 -> 1.3932264 | F40: =F20/$C20 -> 1.7571381 | G40: =G20/$C20 -> 2.2156211 | H40: =H20/$C20 -> 2.713631 | I40: =I20/$C20 -> 3.2286228 | K40: =A40 -> External investors - normal shares | N40: =D40 -> 1.0822895 | O40: =E40 -> 1.3932264 | P40: =F40 -> 1.7571381 | Q40: =G40 -> 2.2156211 | R40: =H40 -> 2.713631 | S40: =I40 -> 3.2286228
C42: 46113 | D42: 46478 | E42: 46844 | F42: 47209 | G42: 47574 | H42: 47939 | I42: 48305
C43: Investment amount | D43: Y1 | E43: Y2 | F43: Y3 | G43: Y4 | H43: Y5 | I43: Y6 | J43: IRR
A44: =A38 -> BFC | C44: =$C$23*-1 -> -16217.891 | D44: =D18 -> 18034.44 | J44: =IF(C44<>0,(XIRR(C44:I44,$C$42:$I$42,)),0) -> 0.11200891
A45: =A39 -> MBI | C45: =$C$24*-1 -> -2495.0602 | D45: =D19 -> 2774.5292 | J45: =IF(C45<>0,(XIRR(C45:I45,$C$42:$I$42,)),0) -> 0.11200891
A46: =A40 -> External investors - normal shares | C46: =$C$25*-1 -> -14554.518 | D46: =D20 -> 15752.202 | J46: =IF(C46<>0,(XIRR(C46:I46,$C$42:$I$42,)),0) -> 0.082289532
A47: =A44 -> BFC | C47: =$C$23*-1 -> -16217.891 | E47: =E18 -> 28425.557 | J47: =IF(C47<>0,(XIRR(C47:I47,$C$42:$I$42,)),0) -> 0.32339838
...

Sheet Growth strategies
A1: GROWTH STRATEGIES - BFC VALUE AD
A2: - scaling up farming operations >1.000T
A3: - Developing export markets
A4: - D2C brand (www.macmenuts.com)
A5: - Product development (various roasts /flavors, packaging sizes, sports nutricion, etc)
A6: - waste product usage (nut oil, dust (cosmetics), pellets (fuel)
A7: - Agriturism

Sheet AI Case analysis
A1: Valuation & Exit Sensitivity
A2: Terminal Value Dependency: The business case relies disproportionately on the exit valuation (Year 6). The Equity Value in 2031 (165m ZAR) is nearly 5x the entry Equity Value (33m ZAR). This assumes a guaranteed 6x EBITDA multiple at exit. A compression to 4x or 5x (common in agricultural down-cycles) would obliterate the projected IRR.
A3: EBITDA Multiple Assumption: The entry implies an EV/EBITDA of ~6x (90m EV / ~15m EBITDA in 2026). Modeling an exit at the same multiple assumes market sentiment and risk appetite remain identical in 2031. This is a neutral, not conservative, baseline.
A4: NAV vs. Earnings: The Net Asset Value (NAV) floor is set at 85m ZAR. The model assumes NAV grows with inflation. If land prices stagnate, the "floor" for the exit valuation lowers.
A5: Production & Revenue Assumptions
A6: Yield Ramp-Up: Production volume grows from 547 tons (2026) to 636 tons (2031)—a 16% increase.
A7: Validation: Most trees (e.g., blocks 1-9) were planted in 2015/2016. In 2026, they are 10-11 years old. Macadamias typically reach full maturity/plateau at 12-15 years. The projected growth aligns with the biological lifecycle, but leaves little room for environmental shocks (drought, pests).
A8: Price Stability Illusion: Revenue growth is driven by both volume and price escalation.
A9: Base Prices: The model uses 2026 base prices of R48/kg (695 Beaumont) to R61.5/kg (816).
A10: Inflationary Peg: Prices escalate strictly at ~4% inflation annually. This assumes constant real prices.
A11: Risk: Global macadamia supply is increasing (major plantings in SA, China, Vietnam). If global supply outpaces demand, real prices will drop. A flat or negative price growth scenario should be stress-tested.
A12: Cost Structure & Capex
... A33: 4. Assumption of constant real prices despite rising global supply.
